Workbook

Sheet System
A1: description | B1: name | C1: value
A2: Attribute Hiding Factor | B2: AHF | C2: 0
A3: Attribute Inheritance Factor | B3: AIF | C3: 0,055
A4: Coupling Factor | B4: CF | C4: 0,5109
A5: Effectiveness | B5: Effectiveness | C5: 2,0114
A6: Extendibility | B6: Extendibility | C6: 2,6756
A7: Flexibility | B7: Flexibility | C7: 4,0285
A8: Functionality | B8: Functionality | C8: 2,5263
A9: Halstead Difficulty | B9: PRHD | C9: 1082,0668
A10: Halstead Effort | B10: PRCHEF | C10: 2944017,9992
A11: Halstead Errors | B11: PRCHER | C11: 14,6596
A12: Halstead Length | B12: PRCHL | C12: 4714
... A30: Understandability | B30: Understandability | C30: -3,3922

Sheet Package
A1: name2 | B1: description3 | C1: name4 | D1: value5
A2: battleship | B2: Abstractness | C2: A | D2: 0,3
A3: battleship | B3: Afferent Coupling | C3: Ca | D3: 1
A4: battleship | B4: Efferent Coupling | C4: Ce | D4: 20
A5: battleship | B5: Halstead Difficulty | C5: PAHD | D5: 856,6456
A6: battleship | B6: Halstead Effort | C6: PACHEF | D6: 2612180,4839
A7: battleship | B7: Halstead Errors | C7: PACHER | D7: 12,2573
A8: battleship | B8: Halstead Length | C8: PACHL | D8: 3801
A9: battleship | B9: Halstead Vocabulary | C9: PACHVC | D9: 1122
A10: battleship | B10: Halstead Volume | C10: PAHVL | D10: 25872,8765
A11: battleship | B11: Instability | C11: I | D11: 0,9524
A12: battleship | B12: Lines Of Code | C12: PLOC | D12: 1965
... A45: restserver | B45: Number Of Static Classes | C45: PNOSC | D45: 0

Sheet Class
A1: name6 | B1: description7 | C1: name8 | D1: value9
A3: Barge | B3: Access To Foreign Data | C3: ATFD | D3: 1
A4: Barge | B4: Cognitive Complexity | C4: CCC | D4: 0
A5: Barge | B5: Coupling Between Objects | C5: CBO | D5: 5
A6: Barge | B6: Data Abstraction Coupling | C6: DAC | D6: 0
A7: Barge | B7: Depth Of Inheritance Tree | C7: DIT | D7: 2
A8: Barge | B8: Halstead Difficulty | C8: CHD | D8: 7,5
A9: Barge | B9: Halstead Effort | C9: CHEF | D9: 485,4378
A10: Barge | B10: Halstead Errors | C10: CHER | D10: 0,0206
A11: Barge | B11: Halstead Length | C11: CHL | D11: 17
A12: Barge | B12: Halstead Vocabulary | C12: CHVC | D12: 14
A13: Barge | B13: Halstead Volume | C13: CHVL | D13: 64,725
... A31: Barge | B31: Weighted Methods Per Class | C31: WMC | D31: 1
A32: Barge
A33: Caravel | B33: Access To Foreign Data | C33: ATFD | D33: 1
A34: Caravel | B34: Cognitive Complexity | C34: CCC | D34: 5
A35: Caravel | B35: Coupling Between Objects | C35: CBO | D35: 5
A36: Caravel | B36: Data Abstraction Coupling | C36: DAC | D36: 0
A37: Caravel | B37: Depth Of Inheritance Tree | C37: DIT | D37: 2
A38: Caravel | B38: Halstead Difficulty | C38: CHD | D38: 30,0
A39: Caravel | B39: Halstead Effort | C39: CHEF | D39: 14268,0854
A40: Caravel | B40: Halstead Errors | C40: CHER | D40: 0,1961
A41: Caravel | B41: Halstead Length | C41: CHL | D41: 96
A42: Caravel | B42: Halstead Vocabulary | C42: CHVC | D42: 31
A43: Caravel | B43: Halstead Volume | C43: CHVL | D43: 475,6028
A44: Caravel | B44: Lack Of Cohesion Of Methods | C44: LCOM | D44: 0
... A61: Caravel | B61: Weighted Methods Per Class | C61: WMC | D61: 9
A62: Caravel
A63: Carrack | B63: Access To Foreign Data | C63: ATFD | D63: 1
A64: Carrack | B64: Cognitive Complexity | C64: CCC | D64: 5
A65: Carrack | B65: Coupling Between Objects | C65: CBO | D65: 5
A66: Carrack | B66: Data Abstraction Coupling | C66: DAC | D66: 0
A67: Carrack | B67: Depth Of Inheritance Tree | C67: DIT | D67: 2
A68: Carrack | B68: Halstead Difficulty | C68: CHD | D68: 30,0
A69: Carrack | B69: Halstead Effort | C69: CHEF | D69: 14268,0854
A70: Carrack | B70: Halstead Errors | C70: CHER | D70: 0,1961
A71: Carrack | B71: Halstead Length | C71: CHL | D71: 96
A72: Carrack | B72: Halstead Vocabulary | C72: CHVC | D72: 31
A73: Carrack | B73: Halstead Volume | C73: CHVL | D73: 475,6028
A74: Carrack | B74: Lack Of Cohesion Of Methods | C74: LCOM | D74: 0
...

Sheet Method
A1: name10 | B1: description11 | C1: name12 | D1: value13 | E1: name14 | F1: description15 | G1: name16 | H1: value17 | I1: name18 | J1: description19 | K1: name20 | L1: value21
A3: Barge(Compass, IPosition) | B3: Cognitive Complexity | C3: CCM | D3: 0
A4: Barge(Compass, IPosition) | B4: Condition Nesting Depth | C4: CND | D4: 0
A5: Barge(Compass, IPosition) | B5: Coupling Dispersion | C5: CDISP | D5: 0,6
A6: Barge(Compass, IPosition) | B6: Coupling Intensity | C6: CINT | D6: 5
A7: Barge(Compass, IPosition) | B7: Foreign Data Providers | C7: FDP | D7: 0
A8: Barge(Compass, IPosition) | B8: Halstead Difficulty | C8: HD | D8: 6,0
A9: Barge(Compass, IPosition) | B9: Halstead Effort | C9: HEF | D9: 301,1369
A10: Barge(Compass, IPosition) | B10: Halstead Errors | C10: HER | D10: 0,015
A11: Barge(Compass, IPosition) | B11: Halstead Length | C11: HL | D11: 14
A12: Barge(Compass, IPosition) | B12: Halstead Vocabulary | C12: HVC | D12: 12
A13: Barge(Compass, IPosition) | B13: Halstead Volume | C13: HVL | D13: 50,1895
A14: Barge(Compass, IPosition) | B14: Lines Of Code | C14: LOC | D14: 11
... A1584: readEnemyFire(Scanner) | B1584: Number Of Loops | C1584: NOL | D1584: 0
E1585: ShotResult | F1585: Access To Foreign Data | G1585: ATFD | H1585: 0
E1586: ShotResult | F1586: Cognitive Complexity | G1586: CCC | H1586: 0
E1587: ShotResult | F1587: Coupling Between Objects | G1587: CBO | H1587: 4
E1588: ShotResult | F1588: Data Abstraction Coupling | G1588: DAC | H1588: 1
E1589: ShotResult | F1589: Depth Of Inheritance Tree | G1589: DIT | H1589: 2
E1590: ShotResult | F1590: Halstead Difficulty | G1590: CHD | H1590: 0,0
E1591: ShotResult | F1591: Halstead Effort | G1591: CHEF | H1591: 0,0
E1592: ShotResult | F1592: Halstead Errors | G1592: CHER | H1592: 0,0
E1593: ShotResult | F1593: Halstead Length | G1593: CHL | H1593: 4
E1594: ShotResult | F1594: Halstead Vocabulary | G1594: CHVC | H1594: 2
E1595: ShotResult | F1595: Halstead Volume | G1595: CHVL | H1595: 4,0
E1596: ShotResult | F1596: Lack Of Cohesion Of Methods | G1596: LCOM | H1596: 0
... E1613: ShotResult | F1613: Weighted Methods Per Class | G1613: WMC | H1613: 5
E1614: ShotResult | I1614: ShotResult(boolean, boolean, IShip, boolean) | J1614: Cognitive Complexity | K1614: CCM | L1614: 0
E1615: ShotResult | I1615: ShotResult(boolean, boolean, IShip, boolean) | J1615: Condition Nesting Depth | K1615: CND | L1615: 0
E1616: ShotResult | I1616: ShotResult(boolean, boolean, IShip, boolean) | J1616: Coupling Dispersion | K1616: CDISP | L1616: 0,0
E1617: ShotResult | I1617: ShotResult(boolean, boolean, IShip, boolean) | J1617: Coupling Intensity | K1617: CINT | L1617: 0
E1618: ShotResult | I1618: ShotResult(boolean, boolean, IShip, boolean) | J1618: Foreign Data Providers | K1618: FDP | L1618: 0
E1619: ShotResult | I1619: ShotResult(boolean, boolean, IShip, boolean) | J1619: Halstead Difficulty | K1619: HD | L1619: 0,0
E1620: ShotResult | I1620: ShotResult(boolean, boolean, IShip, boolean) | J1620: Halstead Effort | K1620: HEF | L1620: NaN
E1621: ShotResult | I1621: ShotResult(boolean, boolean, IShip, boolean) | J1621: Halstead Errors | K1621: HER | L1621: NaN
E1622: ShotResult | I1622: ShotResult(boolean, boolean, IShip, boolean) | J1622: Halstead Length | K1622: HL | L1622: 0
E1623: ShotResult | I1623: ShotResult(boolean, boolean, IShip, boolean) | J1623: Halstead Vocabulary | K1623: HVC | L1623: 0
E1624: ShotResult | I1624: ShotResult(boolean, boolean, IShip, boolean) | J1624: Halstead Volume | K1624: HVL | L1624: NaN
E1625: ShotResult | I1625: ShotResult(boolean, boolean, IShip, boolean) | J1625: Lines Of Code | K1625: LOC | L1625: 4
... E1713: ShotResult | I1713: valid() | J1713: Number Of Parameters | K1713: NOPM | L1713: 0
...

Sheet Metodo_limpo
A1: Coluna1 | B1: Coluna2 | C1: Coluna3 | D1: ID
A2: Barge(Compass, IPosition) | B2: CCM | C2: 0 | D2: 1
A3: Barge(Compass, IPosition) | B3: CND | C3: 0 | D3: =IF(B3="CCM", D2+1, D2) -> 1
A4: Barge(Compass, IPosition) | B4: CDISP | C4: 0.6 | D4: =IF(B4="CCM", D3+1, D3) -> 1
A5: Barge(Compass, IPosition) | B5: CINT | C5: 5 | D5: =IF(B5="CCM", D4+1, D4) -> 1
A6: Barge(Compass, IPosition) | B6: FDP | C6: 0 | D6: =IF(B6="CCM", D5+1, D5) -> 1
A7: Barge(Compass, IPosition) | B7: HD | C7: 6 | D7: =IF(B7="CCM", D6+1, D6) -> 1
A8: Barge(Compass, IPosition) | B8: HEF | C8: 301.1369 | D8: =IF(B8="CCM", D7+1, D7) -> 1
A9: Barge(Compass, IPosition) | B9: HER | C9: 0.015 | D9: =IF(B9="CCM", D8+1, D8) -> 1
A10: Barge(Compass, IPosition) | B10: HL | C10: 14 | D10: =IF(B10="CCM", D9+1, D9) -> 1
A11: Barge(Compass, IPosition) | B11: HVC | C11: 12 | D11: =IF(B11="CCM", D10+1, D10) -> 1
A12: Barge(Compass, IPosition) | B12: HVL | C12: 50.1895 | D12: =IF(B12="CCM", D11+1, D11) -> 1
A13: Barge(Compass, IPosition) | B13: LOC | C13: 11 | D13: =IF(B13="CCM", D12+1, D12) -> 1
A14: Barge(Compass, IPosition) | B14: LAA | C14: 0 | D14: =IF(B14="CCM", D13+1, D13) -> 1
... A167: valueOf(String) | B167: HD | C167: 0 | D167: =IF(B167="CCM", D166+1, D166) -> 9
A168: valueOf(String) | B168: HEF | C168: NaN | D168: =IF(B168="CCM", D167+1, D167) -> 9
A169: valueOf(String) | B169: HER | C169: NaN | D169: =IF(B169="CCM", D168+1, D168) -> 9
A170: valueOf(String) | B170: HL | C170: 0 | D170: =IF(B170="CCM", D169+1, D169) -> 9
A171: valueOf(String) | B171: HVC | C171: 0 | D171: =IF(B171="CCM", D170+1, D170) -> 9
A172: valueOf(String) | B172: HVL | C172: NaN | D172: =IF(B172="CCM", D171+1, D171) -> 9
A173: valueOf(String) | B173: LOC | C173: 0 | D173: =IF(B173="CCM", D172+1, D172) -> 9
A174: valueOf(String) | B174: LAA | C174: 0 | D174: =IF(B174="CCM", D173+1, D173) -> 9
A175: valueOf(String) | B175: LND | C175: 0 | D175: =IF(B175="CCM", D174+1, D174) -> 9
A176: valueOf(String) | B176: MMI | C176: 0 | D176: =IF(B176="CCM", D175+1, D175) -> 9
A177: valueOf(String) | B177: MND | C177: -1 | D177: =IF(B177="CCM", D176+1, D176) -> 9
A178: valueOf(String) | B178: CC | C178: 1 | D178: =IF(B178="CCM", D177+1, D177) -> 9
A179: valueOf(String) | B179: NOAV | C179: 0 | D179: =IF(B179="CCM", D178+1, D178) -> 9
A180: valueOf(String) | B180: NOL | C180: 0 | D180: =IF(B180="CCM", D179+1, D179) -> 9
A181: valueOf(String) | B181: NOPM | C181: 1 | D181: =IF(B181="CCM", D180+1, D180) -> 9
A182: values() | B182: CCM | C182: 0 | D182: =IF(B182="CCM", D181+1, D181) -> 10
A183: values() | B183: CND | C183: 0 | D183: =IF(B183="CCM", D182+1, D182) -> 10
A184: values() | B184: CDISP | C184: 0 | D184: =IF(B184="CCM", D183+1, D183) -> 10
... A187: values() | B187: HD | C187: 0 | D187: =IF(B187="CCM", D186+1, D186) -> 10
A188: values() | B188: HEF | C188: NaN | D188: =IF(B188="CCM", D187+1, D187) -> 10
A189: values() | B189: HER | C189: NaN | D189: =IF(B189="CCM", D188+1, D188) -> 10
A190: values() | B190: HL | C190: 0 | D190: =IF(B190="CCM", D189+1, D189) -> 10
A191: values() | B191: HVC | C191: 0 | D191: =IF(B191="CCM", D190+1, D190) -> 10
A192: values() | B192: HVL | C192: NaN | D192: =IF(B192="CCM", D191+1, D191) -> 10
A193: values() | B193: LOC | C193: 0 | D193: =IF(B193="CCM", D192+1, D192) -> 10
A194: values() | B194: LAA | C194: 0 | D194: =IF(B194="CCM", D193+1, D193) -> 10
...

Sheet Metricas Final
A1: ID | B1: Método | C1: CC | D1: NOPM | E1: LOC | F1: CC NORM | G1: NOPM NORM | H1: LOC NORM | I1: SOMA
A2: 109 | B2: =INDEX(Metodo_limpo!A:A, MATCH(A2, Metodo_limpo!D:D, 0)) -> processEnemyFire(boolean) | C2: =SUMIFS(Metodo_limpo!C:C, Metodo_limpo!D:D, A2, Metodo_limpo!B:B, "CC") -> 37 | D2: =SUMIFS(Metodo_limpo!C:C, Metodo_limpo!D:D, A2, Metodo_limpo!B:B, "NOPM") -> 0 | E2: =SUMIFS(Metodo_limpo!C:C, Metodo_limpo!D:D, A2, Metodo_limpo!B:B, "LOC") -> 138 | F2: =(C2-MIN(C$2:C$169))/(MAX(C$2:C$169)-MIN(C$2:C$169)) -> 1 | G2: =(D2-MIN(D$2:D$169))/(MAX(D$2:D$169)-MIN(D$2:D$169)) -> 0 | H2: =(E2-MIN(E$2:E$169))/(MAX(E$2:E$169)-MIN(E$2:E$169)) -> 1 | I2: =F2+G2+H2 -> 2
A3: 46 | B3: =INDEX(Metodo_limpo!A:A, MATCH(A3, Metodo_limpo!D:D, 0)) -> printBoard(IFleet, List<IMove>, boolean, boolean) | C3: =SUMIFS(Metodo_limpo!C:C, Metodo_limpo!D:D, A3, Metodo_limpo!B:B, "CC") -> 5 | D3: =SUMIFS(Metodo_limpo!C:C, Metodo_limpo!D:D, A3, Metodo_limpo!B:B, "NOPM") -> 4 | E3: =SUMIFS(Metodo_limpo!C:C, Metodo_limpo!D:D, A3, Metodo_limpo!B:B, "LOC") -> 32 | F3: =(C3-MIN(C$2:C$169))/(MAX(C$2:C$169)-MIN(C$2:C$169)) -> 0.13513514 | G3: =(D3-MIN(D$2:D$169))/(MAX(D$2:D$169)-MIN(D$2:D$169)) -> 1 | H3: =(E3-MIN(E$2:E$169))/(MAX(E$2:E$169)-MIN(E$2:E$169)) -> 0.23188406 | I3: =F3+G3+H3 -> 1.3670192
A4: 148 | B4: =INDEX(Metodo_limpo!A:A, MATCH(A4, Metodo_limpo!D:D, 0)) -> receiveShots(String, ShotRequest) | C4: =SUMIFS(Metodo_limpo!C:C, Metodo_limpo!D:D, A4, Metodo_limpo!B:B, "CC") -> 12 | D4: =SUMIFS(Metodo_limpo!C:C, Metodo_limpo!D:D, A4, Metodo_limpo!B:B, "NOPM") -> 2 | E4: =SUMIFS(Metodo_limpo!C:C, Metodo_limpo!D:D, A4, Metodo_limpo!B:B, "LOC") -> 60 | F4: =(C4-MIN(C$2:C$169))/(MAX(C$2:C$169)-MIN(C$2:C$169)) -> 0.32432432 | G4: =(D4-MIN(D$2:D$169))/(MAX(D$2:D$169)-MIN(D$2:D$169)) -> 0.5 | H4: =(E4-MIN(E$2:E$169))/(MAX(E$2:E$169)-MIN(E$2:E$169)) -> 0.43478261 | I4: =F4+G4+H4 -> 1.2591069
A5: 120 | B5: =INDEX(Metodo_limpo!A:A, MATCH(A5, Metodo_limpo!D:D, 0)) -> buildShip(String, Compass, Position) | C5: =SUMIFS(Metodo_limpo!C:C, Metodo_limpo!D:D, A5, Metodo_limpo!B:B, "CC") -> 7 | D5: =SUMIFS(Metodo_limpo!C:C, Metodo_limpo!D:D, A5, Metodo_limpo!B:B, "NOPM") -> 3 | E5: =SUMIFS(Metodo_limpo!C:C, Metodo_limpo!D:D, A5, Metodo_limpo!B:B, "LOC") -> 36 | F5: =(C5-MIN(C$2:C$169))/(MAX(C$2:C$169)-MIN(C$2:C$169)) -> 0.18918919 | G5: =(D5-MIN(D$2:D$169))/(MAX(D$2:D$169)-MIN(D$2:D$169)) -> 0.75 | H5: =(E5-MIN(E$2:E$169))/(MAX(E$2:E$169)-MIN(E$2:E$169)) -> 0.26086957 | I5: =F5+G5+H5 -> 1.2000588
A6: 144 | B6: =INDEX(Metodo_limpo!A:A, MATCH(A6, Metodo_limpo!D:D, 0)) -> sendShots(GameSession, List<IPosition>) | C6: =SUMIFS(Metodo_limpo!C:C, Metodo_limpo!D:D, A6, Metodo_limpo!B:B, "CC") -> 9 | D6: =SUMIFS(Metodo_limpo!C:C, Metodo_limpo!D:D, A6, Metodo_limpo!B:B, "NOPM") -> 2 | E6: =SUMIFS(Metodo_limpo!C:C, Metodo_limpo!D:D, A6, Metodo_limpo!B:B, "LOC") -> 62 | F6: =(C6-MIN(C$2:C$169))/(MAX(C$2:C$169)-MIN(C$2:C$169)) -> 0.24324324 | G6: =(D6-MIN(D$2:D$169))/(MAX(D$2:D$169)-MIN(D$2:D$169)) -> 0.5 | H6: =(E6-MIN(E$2:E$169))/(MAX(E$2:E$169)-MIN(E$2:E$169)) -> 0.44927536 | I6: =F6+G6+H6 -> 1.1925186
A7: 147 | B7: =INDEX(Metodo_limpo!A:A, MATCH(A7, Metodo_limpo!D:D, 0)) -> evaluateShots(List<IPosition>, IGame, GameSession) | C7: =SUMIFS(Metodo_limpo!C:C, Metodo_limpo!D:D, A7, Metodo_limpo!B:B, "CC") -> 6 | D7: =SUMIFS(Metodo_limpo!C:C, Metodo_limpo!D:D, A7, Metodo_limpo!B:B, "NOPM") -> 3 | E7: =SUMIFS(Metodo_limpo!C:C, Metodo_limpo!D:D, A7, Metodo_limpo!B:B, "LOC") -> 38 | F7: =(C7-MIN(C$2:C$169))/(MAX(C$2:C$169)-MIN(C$2:C$169)) -> 0.16216216 | G7: =(D7-MIN(D$2:D$169))/(MAX(D$2:D$169)-MIN(D$2:D$169)) -> 0.75 | H7: =(E7-MIN(E$2:E$169))/(MAX(E$2:E$169)-MIN(E$2:E$169)) -> 0.27536232 | I7: =F7+G7+H7 -> 1.1875245
A8: 119 | B8: =INDEX(Metodo_limpo!A:A, MATCH(A8, Metodo_limpo!D:D, 0)) -> Ship(String, Compass, IPosition, int) | C8: =SUMIFS(Metodo_limpo!C:C, Metodo_limpo!D:D, A8, Metodo_limpo!B:B, "CC") -> 1 | D8: =SUMIFS(Metodo_limpo!C:C, Metodo_limpo!D:D, A8, Metodo_limpo!B:B, "NOPM") -> 4 | E8: =SUMIFS(Metodo_limpo!C:C, Metodo_limpo!D:D, A8, Metodo_limpo!B:B, "LOC") -> 19 | F8: =(C8-MIN(C$2:C$169))/(MAX(C$2:C$169)-MIN(C$2:C$169)) -> 0.027027027 | G8: =(D8-MIN(D$2:D$169))/(MAX(D$2:D$169)-MIN(D$2:D$169)) -> 1 | H8: =(E8-MIN(E$2:E$169))/(MAX(E$2:E$169)-MIN(E$2:E$169)) -> 0.13768116 | I8: =F8+G8+H8 -> 1.1647082
A9: 140 | B9: =INDEX(Metodo_limpo!A:A, MATCH(A9, Metodo_limpo!D:D, 0)) -> computeShots(IGame) | C9: =SUMIFS(Metodo_limpo!C:C, Metodo_limpo!D:D, A9, Metodo_limpo!B:B, "CC") -> 19 | D9: =SUMIFS(Metodo_limpo!C:C, Metodo_limpo!D:D, A9, Metodo_limpo!B:B, "NOPM") -> 1 | E9: =SUMIFS(Metodo_limpo!C:C, Metodo_limpo!D:D, A9, Metodo_limpo!B:B, "LOC") -> 55 | F9: =(C9-MIN(C$2:C$169))/(MAX(C$2:C$169)-MIN(C$2:C$169)) -> 0.51351351 | G9: =(D9-MIN(D$2:D$169))/(MAX(D$2:D$169)-MIN(D$2:D$169)) -> 0.25 | H9: =(E9-MIN(E$2:E$169))/(MAX(E$2:E$169)-MIN(E$2:E$169)) -> 0.39855072 | I9: =F9+G9+H9 -> 1.1620642
A10: 134 | B10: =INDEX(Metodo_limpo!A:A, MATCH(A10, Metodo_limpo!D:D, 0)) -> menu() | C10: =SUMIFS(Metodo_limpo!C:C, Metodo_limpo!D:D, A10, Metodo_limpo!B:B, "CC") -> 20 | D10: =SUMIFS(Metodo_limpo!C:C, Metodo_limpo!D:D, A10, Metodo_limpo!B:B, "NOPM") -> 0 | E10: =SUMIFS(Metodo_limpo!C:C, Metodo_limpo!D:D, A10, Metodo_limpo!B:B, "LOC") -> 74 | F10: =(C10-MIN(C$2:C$169))/(MAX(C$2:C$169)-MIN(C$2:C$169)) -> 0.54054054 | G10: =(D10-MIN(D$2:D$169))/(MAX(D$2:D$169)-MIN(D$2:D$169)) -> 0 | H10: =(E10-MIN(E$2:E$169))/(MAX(E$2:E$169)-MIN(E$2:E$169)) -> 0.53623188 | I10: =F10+G10+H10 -> 1.0767724
A11: 163 | B11: =INDEX(Metodo_limpo!A:A, MATCH(A11, Metodo_limpo!D:D, 0)) -> ShotResult(boolean, boolean, IShip, boolean) | C11: =SUMIFS(Metodo_limpo!C:C, Metodo_limpo!D:D, A11, Metodo_limpo!B:B, "CC") -> 1 | D11: =SUMIFS(Metodo_limpo!C:C, Metodo_limpo!D:D, A11, Metodo_limpo!B:B, "NOPM") -> 4 | E11: =SUMIFS(Metodo_limpo!C:C, Metodo_limpo!D:D, A11, Metodo_limpo!B:B, "LOC") -> 4 | F11: =(C11-MIN(C$2:C$169))/(MAX(C$2:C$169)-MIN(C$2:C$169)) -> 0.027027027 | G11: =(D11-MIN(D$2:D$169))/(MAX(D$2:D$169)-MIN(D$2:D$169)) -> 1 | H11: =(E11-MIN(E$2:E$169))/(MAX(E$2:E$169)-MIN(E$2:E$169)) -> 0.028985507 | I11: =F11+G11+H11 -> 1.0560125
A12: 143 | B12: =INDEX(Metodo_limpo!A:A, MATCH(A12, Metodo_limpo!D:D, 0)) -> recordAiMove(IGame, List<IPosition>, ShotResponse) | C12: =SUMIFS(Metodo_limpo!C:C, Metodo_limpo!D:D, A12, Metodo_limpo!B:B, "CC") -> 4 | D12: =SUMIFS(Metodo_limpo!C:C, Metodo_limpo!D:D, A12, Metodo_limpo!B:B, "NOPM") -> 3 | E12: =SUMIFS(Metodo_limpo!C:C, Metodo_limpo!D:D, A12, Metodo_limpo!B:B, "LOC") -> 20 | F12: =(C12-MIN(C$2:C$169))/(MAX(C$2:C$169)-MIN(C$2:C$169)) -> 0.10810811 | G12: =(D12-MIN(D$2:D$169))/(MAX(D$2:D$169)-MIN(D$2:D$169)) -> 0.75 | H12: =(E12-MIN(E$2:E$169))/(MAX(E$2:E$169)-MIN(E$2:E$169)) -> 0.14492754 | I12: =F12+G12+H12 -> 1.0030356
A13: 55 | B13: =INDEX(Metodo_limpo!A:A, MATCH(A13, Metodo_limpo!D:D, 0)) -> addComponentsMenu() | C13: =SUMIFS(Metodo_limpo!C:C, Metodo_limpo!D:D, A13, Metodo_limpo!B:B, "CC") -> 14 | D13: =SUMIFS(Metodo_limpo!C:C, Metodo_limpo!D:D, A13, Metodo_limpo!B:B, "NOPM") -> 0 | E13: =SUMIFS(Metodo_limpo!C:C, Metodo_limpo!D:D, A13, Metodo_limpo!B:B, "LOC") -> 84 | F13: =(C13-MIN(C$2:C$169))/(MAX(C$2:C$169)-MIN(C$2:C$169)) -> 0.37837838 | G13: =(D13-MIN(D$2:D$169))/(MAX(D$2:D$169)-MIN(D$2:D$169)) -> 0 | H13: =(E13-MIN(E$2:E$169))/(MAX(E$2:E$169)-MIN(E$2:E$169)) -> 0.60869565 | I13: =F13+G13+H13 -> 0.98707403
... A169: 126 | B169: =INDEX(Metodo_limpo!A:A, MATCH(A169, Metodo_limpo!D:D, 0)) -> isInsideBoard() | C169: =SUMIFS(Metodo_limpo!C:C, Metodo_limpo!D:D, A169, Metodo_limpo!B:B, "CC") -> 0 | D169: =SUMIFS(Metodo_limpo!C:C, Metodo_limpo!D:D, A169, Metodo_limpo!B:B, "NOPM") -> 0 | E169: =SUMIFS(Metodo_limpo!C:C, Metodo_limpo!D:D, A169, Metodo_limpo!B:B, "LOC") -> 0 | F169: =(C169-MIN(C$2:C$169))/(MAX(C$2:C$169)-MIN(C$2:C$169)) -> 0 | G169: =(D169-MIN(D$2:D$169))/(MAX(D$2:D$169)-MIN(D$2:D$169)) -> 0 | H169: =(E169-MIN(E$2:E$169))/(MAX(E$2:E$169)-MIN(E$2:E$169)) -> 0 | I169: =F169+G169+H169 -> 0
